<?xml version="1.0" encoding="utf-8"?>
<!-- This URDF was automatically created by SolidWorks to URDF Exporter! Originally created by Stephen Brawner (brawner@gmail.com) 
     Commit Version: 1.6.0-1-g15f4949  Build Version: 1.6.7594.29634
     For more information, please see http://wiki.ros.org/sw_urdf_exporter -->
<robot
  name="ROBOT_URDF">

  <link name="world"/>
  <joint name="base_joint" type="fixed">
	<parent link="world"/>
	<child link="base_link"/>
	<origin rpy="0 0 0" xyz="0.0 0.0 0.0"/>
  </joint>

  <link
    name="base_link">
    <inertial>
      <origin
        xyz="4.1633E-17 0 0.11582"
        rpy="0 0 0" />
      <mass
        value="25" />
      <inertia
        ixx="3.8948"
        ixy="1.0435E-16"
        ixz="5.2941E-16"
        iyy="3.8948"
        iyz="7.5513E-16"
        izz="4.4192" />
    </inertial>
    <visual>
      <origin
        xyz="0 0 0"
        rpy="0 0 0" />
      <geometry>
        <mesh
          filename="package://ROBOT_URDF/meshes/base_link.STL" />
      </geometry>
      <material
        name="">
        <color
          rgba="0.64706 0.61961 0.58824 1" />
      </material>
    </visual>
    <collision>
      <origin
        xyz="0 0 0"
        rpy="0 0 0" />
      <geometry>
        <mesh
          filename="package://ROBOT_URDF/meshes/base_link.STL" />
      </geometry>
    </collision>
  </link>
  <link
    name="link_1">
    <inertial>
      <origin
        xyz="4.9234E-11 0.25596 5.0492E-10"
        rpy="0 0 0" />
      <mass
        value="17.439" />
      <inertia
        ixx="0.48938"
        ixy="-3.4442E-10"
        ixz="3.0905E-09"
        iyy="0.29622"
        iyz="4.4642E-10"
        izz="0.47585" />
    </inertial>
    <visual>
      <origin
        xyz="0 0 0"
        rpy="0 0 0" />
      <geometry>
        <mesh
          filename="package://ROBOT_URDF/meshes/link_1.STL" />
      </geometry>
      <material
        name="">
        <color
          rgba="0.79216 0.81961 0.93333 1" />
      </material>
    </visual>
    <collision>
      <origin
        xyz="0 0 0"
        rpy="0 0 0" />
      <geometry>
        <mesh
          filename="package://ROBOT_URDF/meshes/link_1.STL" />
      </geometry>
    </collision>
  </link>
  <joint
    name="joint_1"
    type="revolute">
    <origin
      xyz="0 0 0.20418"
      rpy="1.5708 0 1.5708" />
    <parent
      link="base_link" />
    <child
      link="link_1" />
    <axis
      xyz="0 1 0" />
    <limit
      lower="0"
      upper="6.283"
      effort="600"
      velocity="3" />
  </joint>
  <link
    name="link_2">
    <inertial>
      <origin
        xyz="4.1177E-09 0.28717 4.1633E-17"
        rpy="0 0 0" />
      <mass
        value="20" />
      <inertia
        ixx="1.8703"
        ixy="-2.4397E-08"
        ixz="-3.6992E-18"
        iyy="0.16879"
        iyz="-1.6658E-16"
        izz="1.9116" />
    </inertial>
    <visual>
      <origin
        xyz="0 0 0"
        rpy="0 0 0" />
      <geometry>
        <mesh
          filename="package://ROBOT_URDF/meshes/link_2.STL" />
      </geometry>
      <material
        name="">
        <color
          rgba="0.79216 0.81961 0.93333 1" />
      </material>
    </visual>
    <collision>
      <origin
        xyz="0 0 0"
        rpy="0 0 0" />
      <geometry>
        <mesh
          filename="package://ROBOT_URDF/meshes/link_2.STL" />
      </geometry>
    </collision>
  </link>
  <joint
    name="joint_2"
    type="revolute">
    <origin
      xyz="0 0.44368 0"
      rpy="0 0 0" />
    <parent
      link="link_1" />
    <child
      link="link_2" />
    <axis
      xyz="0 0 1" />
    <limit
      lower="-1.57"
      upper="1.57"
      effort="600"
      velocity="3" />
  </joint>
  <link
    name="link_3">
    <inertial>
      <origin
        xyz="-0.30674 2.2204E-16 3.4694E-16"
        rpy="0 0 0" />
      <mass
        value="14.238" />
      <inertia
        ixx="0.10962"
        ixy="-3.0948E-13"
        ixz="-1.1673E-15"
        iyy="0.42271"
        iyz="-2.5111E-09"
        izz="0.37203" />
    </inertial>
    <visual>
      <origin
        xyz="0 0 0"
        rpy="0 0 0" />
      <geometry>
        <mesh
          filename="package://ROBOT_URDF/meshes/link_3.STL" />
      </geometry>
      <material
        name="">
        <color
          rgba="0.79216 0.81961 0.93333 1" />
      </material>
    </visual>
    <collision>
      <origin
        xyz="0 0 0"
        rpy="0 0 0" />
      <geometry>
        <mesh
          filename="package://ROBOT_URDF/meshes/link_3.STL" />
      </geometry>
    </collision>
  </link>
  <joint
    name="joint_3"
    type="revolute">
    <origin
      xyz="0 0.68571 0"
      rpy="0 0 0" />
    <parent
      link="link_2" />
    <child
      link="link_3" />
    <axis
      xyz="0 0 1" />
    <limit
      lower="-3.142"
      upper="0.785"
      effort="550"
      velocity="3" />
  </joint>
  <link
    name="link_4">
    <inertial>
      <origin
        xyz="-0.24009 -3.8215E-11 -6.6828E-11"
        rpy="0 0 0" />
      <mass
        value="10" />
      <inertia
        ixx="0.23135"
        ixy="5.4326E-10"
        ixz="7.1373E-10"
        iyy="2.7601"
        iyz="-4.604E-08"
        izz="2.6782" />
    </inertial>
    <visual>
      <origin
        xyz="0 0 0"
        rpy="0 0 0" />
      <geometry>
        <mesh
          filename="package://ROBOT_URDF/meshes/link_4.STL" />
      </geometry>
      <material
        name="">
        <color
          rgba="0.64706 0.61961 0.58824 1" />
      </material>
    </visual>
    <collision>
      <origin
        xyz="0 0 0"
        rpy="0 0 0" />
      <geometry>
        <mesh
          filename="package://ROBOT_URDF/meshes/link_4.STL" />
      </geometry>
    </collision>
  </link>
  <joint
    name="joint_4"
    type="revolute">
    <origin
      xyz="-0.6 0 0"
      rpy="0 0 0.028575" />
    <parent
      link="link_3" />
    <child
      link="link_4" />
    <axis
      xyz="0 0 1" />
    <limit
      lower="-1.57"
      upper="1.57"
      effort="500"
      velocity="3" />
  </joint>
  <link
    name="link_5">
    <inertial>
      <origin
        xyz="0.4852 0.0575 -2.6151E-08"
        rpy="0 0 0" />
      <mass
        value="7" />
      <inertia
        ixx="0.1363"
        ixy="8.2801E-08"
        ixz="9.4865E-08"
        iyy="3.488"
        iyz="1.0712E-06"
        izz="3.4449" />
    </inertial>
    <visual>
      <origin
        xyz="0 0 0"
        rpy="0 0 0" />
      <geometry>
        <mesh
          filename="package://ROBOT_URDF/meshes/link_5.STL" />
      </geometry>
      <material
        name="">
        <color
          rgba="0.64706 0.61961 0.58824 1" />
      </material>
    </visual>
    <collision>
      <origin
        xyz="0 0 0"
        rpy="0 0 0" />
      <geometry>
        <mesh
          filename="package://ROBOT_URDF/meshes/link_5.STL" />
      </geometry>
    </collision>
  </link>
  <joint
    name="joint_5"
    type="prismatic">
    <origin
      xyz="-0.17029 -0.0575 0"
      rpy="3.1416 0 3.1416" />
    <parent
      link="link_4" />
    <child
      link="link_5" />
    <axis
      xyz="-1 0 0" />
    <limit
      lower="-0.4"
      upper="0"
      effort="500"
      velocity="0.5" />
  </joint>
  <link
    name="link_6">
    <inertial>
      <origin
        xyz="1.5111E-07 -1.4058E-06 0.20422"
        rpy="0 0 0" />
      <mass
        value="5" />
      <inertia
        ixx="0.96634"
        ixy="-2.3215E-06"
        ixz="5.6083E-07"
        iyy="1.1351"
        iyz="2.0425E-05"
        izz="0.37223" />
    </inertial>
    <visual>
      <origin
        xyz="0 0 0"
        rpy="0 0 0" />
      <geometry>
        <mesh
          filename="package://ROBOT_URDF/meshes/link_6.STL" />
      </geometry>
      <material
        name="">
        <color
          rgba="0.64706 0.61961 0.58824 1" />
      </material>
    </visual>
    <collision>
      <origin
        xyz="0 0 0"
        rpy="0 0 0" />
      <geometry>
        <mesh
          filename="package://ROBOT_URDF/meshes/link_6.STL" />
      </geometry>
    </collision>
  </link>
  <joint
    name="joint_6"
    type="revolute">
    <origin
      xyz="0.74623 0.0575 0"
      rpy="1.5708 1.5708 0" />
    <parent
      link="link_5" />
    <child
      link="link_6" />
    <axis
      xyz="1 0 0" />
    <limit
      lower="-4.04"
      upper="0.785"
      effort="400"
      velocity="3" />
  </joint>
  <link
    name="gripper_right">
    <inertial>
      <origin
        xyz="-0.047546 0.06 0.07387"
        rpy="0 0 0" />
      <mass
        value="0.3" />
      <inertia
        ixx="0.027332"
        ixy="3.1919E-09"
        ixz="-0.0024985"
        iyy="0.021983"
        iyz="1.4201E-08"
        izz="0.014327" />
    </inertial>
    <visual>
      <origin
        xyz="0 0 0"
        rpy="0 0 0" />
      <geometry>
        <mesh
          filename="package://ROBOT_URDF/meshes/gripper_right.STL" />
      </geometry>
      <material
        name="">
        <color
          rgba="0.64706 0.61961 0.58824 1" />
      </material>
    </visual>
    <collision>
      <origin
        xyz="0 0 0"
        rpy="0 0 0" />
      <geometry>
        <mesh
          filename="package://ROBOT_URDF/meshes/gripper_right.STL" />
      </geometry>
    </collision>
  </link>
  <joint
    name="joint_7"
    type="prismatic">
    <origin
      xyz="0 -0.06 0.4"
      rpy="0 0 0" />
    <parent
      link="link_6" />
    <child
      link="gripper_right" />
    <axis
      xyz="-1 0 0" />
    <limit
      lower="0"
      upper="0.05"
      effort="300"
      velocity="0.5" />
  </joint>
  <link
    name="gripper_left">
    <inertial>
      <origin
        xyz="-0.047546 0.06 0.07387"
        rpy="0 0 0" />
      <mass
        value="0.3" />
      <inertia
        ixx="0.027332"
        ixy="3.1626E-09"
        ixz="-0.0024985"
        iyy="0.021983"
        iyz="1.4212E-08"
        izz="0.014327" />
    </inertial>
    <visual>
      <origin
        xyz="0 0 0"
        rpy="0 0 0" />
      <geometry>
        <mesh
          filename="package://ROBOT_URDF/meshes/gripper_left.STL" />
      </geometry>
      <material
        name="">
        <color
          rgba="0.64706 0.61961 0.58824 1" />
      </material>
    </visual>
    <collision>
      <origin
        xyz="0 0 0"
        rpy="0 0 0" />
      <geometry>
        <mesh
          filename="package://ROBOT_URDF/meshes/gripper_left.STL" />
      </geometry>
    </collision>
  </link>
  <joint
    name="joint_8"
    type="prismatic">
    <origin
      xyz="0 0.06 0.4"
      rpy="0 0 3.1416" />
    <parent
      link="link_6" />
    <child
      link="gripper_left" />
    <axis
      xyz="1 0 0" />
    <limit
      lower="-0.05"
      upper="0"
      effort="300"
      velocity="1" />
  </joint>

  <transmission name="link_1_trans">
	<type>transmission_interface/SimpleTransmission</type>
	<joint name="joint_1">
		<hardwareInterface>hardware_interface/PositionJointInterface</hardwareInterface>
	</joint>
	<actuator name="link_1_motor">
		<hardwareInterface>hardware_interface/PositionJointInterface</hardwareInterface>
		<mechanicalReduction>1</mechanicalReduction>
	</actuator>
  </transmission>

  <transmission name="link_2_trans">
	<type>transmission_interface/SimpleTransmission</type>
	<joint name="joint_2">
		<hardwareInterface>hardware_interface/PositionJointInterface</hardwareInterface>
	</joint>
	<actuator name="link_2_motor">
		<hardwareInterface>hardware_interface/PositionJointInterface</hardwareInterface>
		<mechanicalReduction>1</mechanicalReduction>
	</actuator>
  </transmission>

  <transmission name="link_3_trans">
	<type>transmission_interface/SimpleTransmission</type>
	<joint name="joint_3">
		<hardwareInterface>hardware_interface/PositionJointInterface</hardwareInterface>
	</joint>
	<actuator name="link_3_motor">
		<hardwareInterface>hardware_interface/PositionJointInterface</hardwareInterface>
		<mechanicalReduction>1</mechanicalReduction>
	</actuator>
  </transmission>

  <transmission name="link_4_trans">
	<type>transmission_interface/SimpleTransmission</type>
	<joint name="joint_4">
		<hardwareInterface>hardware_interface/PositionJointInterface</hardwareInterface>
	</joint>
	<actuator name="link_4_motor">
		<hardwareInterface>hardware_interface/PositionJointInterface</hardwareInterface>
		<mechanicalReduction>1</mechanicalReduction>
	</actuator>
  </transmission>

  <transmission name="link_5_trans">
	<type>transmission_interface/SimpleTransmission</type>
	<joint name="joint_5">
		<hardwareInterface>hardware_interface/PositionJointInterface</hardwareInterface>
	</joint>
	<actuator name="link_5_motor">
		<hardwareInterface>hardware_interface/PositionJointInterface</hardwareInterface>
		<mechanicalReduction>1</mechanicalReduction>
	</actuator>
  </transmission>

  <transmission name="link_6_trans">
	<type>transmission_interface/SimpleTransmission</type>
	<joint name="joint_6">
		<hardwareInterface>hardware_interface/PositionJointInterface</hardwareInterface>
	</joint>
	<actuator name="link_6_motor">
		<hardwareInterface>hardware_interface/PositionJointInterface</hardwareInterface>
		<mechanicalReduction>1</mechanicalReduction>
	</actuator>
  </transmission>

  <transmission name="link_7_trans">
	<type>transmission_interface/SimpleTransmission</type>
	<joint name="joint_7">
		<hardwareInterface>hardware_interface/PositionJointInterface</hardwareInterface>
	</joint>
	<actuator name="link_7_motor">
		<hardwareInterface>hardware_interface/PositionJointInterface</hardwareInterface>
		<mechanicalReduction>1</mechanicalReduction>
	</actuator>
  </transmission>

  <transmission name="link_8_trans">
	<type>transmission_interface/SimpleTransmission</type>
	<joint name="joint_8">
		<hardwareInterface>hardware_interface/PositionJointInterface</hardwareInterface>
	</joint>
	<actuator name="link_8_motor">
		<hardwareInterface>hardware_interface/PositionJointInterface</hardwareInterface>
		<mechanicalReduction>1</mechanicalReduction>
	</actuator>
  </transmission>

  <gazebo>
	<plugin name="control"
		filename="libgazebo_ros_control.so">
		<robotNamespace>/</robotNamespace>
	</plugin>
  </gazebo>

  <gazebo reference="link_1">
	<selfCollide>true</selfCollide>
  </gazebo>

  <gazebo reference="link_2">
	<selfCollide>true</selfCollide>
  </gazebo>

  <gazebo reference="link_3">
	<selfCollide>true</selfCollide>
  </gazebo>

  <gazebo reference="link_4">
	<selfCollide>true</selfCollide>
  </gazebo>

  <gazebo reference="link_5">
	<selfCollide>true</selfCollide>
  </gazebo>

  <gazebo reference="link_6">
	<selfCollide>true</selfCollide>
  </gazebo>

  <gazebo reference="gripper_right">
	<selfCollide>true</selfCollide>
  </gazebo>

  <gazebo reference="gripper_left">
	<selfCollide>true</selfCollide>
  </gazebo>


</robot>
